<?xml version="1.0"?>
<robot name="simple_humanoid">

  <!-- ========================================== -->
  <!--                LINKS                       -->
  <!-- ========================================== -->

  <!-- 1. The Torso (Root) -->
  <link name="base_link">
    <visual>
      <geometry>
        <!-- Box: x=0.3m, y=0.5m, z=0.8m -->
        <box size="0.3 0.5 0.8"/>
      </geometry>
      <material name="blue">
        <color rgba="0 0 1 1"/>
      </material>
    </visual>
    <collision>
      <geometry>
        <box size="0.3 0.5 0.8"/>
      </geometry>
    </collision>
    <inertial>
      <mass value="10.0"/>
      <!-- Simplified inertia tensor for a box -->
      <inertia ixx="1.0" ixy="0.0" ixz="0.0" iyy="1.0" iyz="0.0" izz="1.0"/>
    </inertial>
  </link>

  <!-- 2. The Head -->
  <link name="head">
    <visual>
      <geometry>
        <sphere radius="0.15"/>
      </geometry>
      <material name="white">
        <color rgba="1 1 1 1"/>
      </material>
    </visual>
    <collision>
      <geometry>
        <sphere radius="0.15"/>
      </geometry>
    </collision>
    <inertial>
      <mass value="2.0"/>
      <inertia ixx="0.1" ixy="0.0" ixz="0.0" iyy="0.1" iyz="0.0" izz="0.1"/>
    </inertial>
  </link>

  <!-- 3. The Arm -->
  <link name="arm">
    <visual>
      <geometry>
        <cylinder length="0.6" radius="0.05"/>
      </geometry>
      <material name="red">
        <color rgba="1 0 0 1"/>
      </material>
    </visual>
    <collision>
      <geometry>
        <cylinder length="0.6" radius="0.05"/>
      </geometry>
    </collision>
    <inertial>
      <mass value="1.0"/>
      <inertia ixx="0.05" ixy="0.0" ixz="0.0" iyy="0.05" iyz="0.0" izz="0.01"/>
    </inertial>
  </link>

  <!-- ========================================== -->
  <!--                JOINTS                      -->
  <!-- ========================================== -->

  <!-- 1. Neck: Fixed (Head doesn't move relative to torso) -->
  <joint name="neck" type="fixed">
    <parent link="base_link"/>
    <child link="head"/>
    <!-- Origin: x=0, y=0, z=0.4 (Top of torso) -->
    <origin xyz="0 0 0.4"/>
  </joint>

  <!-- 2. Shoulder: Revolute (Rotates) -->
  <joint name="shoulder" type="revolute">
    <parent link="base_link"/>
    <child link="arm"/>
    <!-- Origin: Side of torso -->
    <origin xyz="0.2 0 0.3"/>
    <!-- Axis: Rotates around Y axis (Pitch) -->
    <axis xyz="0 1 0"/>
    <!-- Limits: Angles in radians -->
    <limit lower="-1.57" upper="1.57" effort="10.0" velocity="1.0"/>
  </joint>

</robot>
